Traceback (most recent call last):
  File "/opt/homebrew/Caskroom/miniforge/base/lib/python3.12/site-packages/jupyter_cache/executors/utils.py", line 58, in single_nb_execution
    executenb(
  File "/opt/homebrew/Caskroom/miniforge/base/lib/python3.12/site-packages/nbclient/client.py", line 1319, in execute
    return NotebookClient(nb=nb, resources=resources, km=km, **kwargs).execute()
           ^^^^^^^^^^^^^^^^^^^^^^^^^^^^^^^^^^^^^^^^^^^^^^^^^^^^^^^^^^^^^^^^^^^^^
  File "/opt/homebrew/Caskroom/miniforge/base/lib/python3.12/site-packages/jupyter_core/utils/__init__.py", line 165, in wrapped
    return loop.run_until_complete(inner)
           ^^^^^^^^^^^^^^^^^^^^^^^^^^^^^^
  File "/opt/homebrew/Caskroom/miniforge/base/lib/python3.12/asyncio/base_events.py", line 686, in run_until_complete
    return future.result()
           ^^^^^^^^^^^^^^^
  File "/opt/homebrew/Caskroom/miniforge/base/lib/python3.12/site-packages/nbclient/client.py", line 709, in async_execute
    await self.async_execute_cell(
  File "/opt/homebrew/Caskroom/miniforge/base/lib/python3.12/site-packages/nbclient/client.py", line 1062, in async_execute_cell
    await self._check_raise_for_error(cell, cell_index, exec_reply)
  File "/opt/homebrew/Caskroom/miniforge/base/lib/python3.12/site-packages/nbclient/client.py", line 918, in _check_raise_for_error
    raise CellExecutionError.from_cell_and_msg(cell, exec_reply_content)
nbclient.exceptions.CellExecutionError: An error occurred while executing the following cell:
------------------
fun1(1)
fun2(1)
fun3(1)
------------------

----- stdout -----
2
3
------------------

[0;31m---------------------------------------------------------------------------[0m
[0;31mNameError[0m                                 Traceback (most recent call last)
Cell [0;32mIn[13], line 3[0m
[1;32m      1[0m fun1([38;5;241m1[39m)
[1;32m      2[0m fun2([38;5;241m1[39m)
[0;32m----> 3[0m [43mfun3[49m[43m([49m[38;5;241;43m1[39;49m[43m)[49m

Cell [0;32mIn[12], line 10[0m, in [0;36mfun3[0;34m(x)[0m
[1;32m      9[0m [38;5;28;01mdef[39;00m[38;5;250m [39m[38;5;21mfun3[39m(x):
[0;32m---> 10[0m     [38;5;28mprint[39m(x [38;5;241m+[39m [43ma[49m)

[0;31mNameError[0m: name 'a' is not defined

